---
title: "多线程学习 如何捕获异常"
date: 2019-11-20T22:54:40+08:00
draft: true
---

## 起因
前一段时间，公司有个任务，两个系统对接，需要通过mq的方式，将他们系统的数据迁移到我们系统中。
我采取了多线程去解决这个任务。
由于数据存在于不同的供应商，我按照供应商的纬度进行开启多线程，用java自带的线程池开了五个线程执行。
当发到测试环境测试时，发现了一个很奇怪的现象：
某个供应商的数据迁移后，缺失了一部分。但若是一条记录一条记录的迁移就没有问题。起初怀疑是执行中出现了异常，但是奇怪的是，我看到了代码执行结束时打印的日志。
由于知道了这个供应商id，并且mq是可以重复运行的，于是我仅仅对该供应商发起消息。
由于数据是一页一页的查询的，查一页处理一页，看日志发现执行到某一页的时候，突然就打印了结束的日志。整个过程中**没有打印任何错误日志**。
百思不得其解，最后在大佬的帮助下，我才发现这几个错误：
1. 服务器上没有所谓的控制台，我们公司的日志是使用log4j来打印的，也就是说如果没有使用类似
    ``` java
    logger.info()
    ```
    的方式打印日志，是不会收集到日志文件中的。
2. 由于线程的本质特性，使得你不能捕获从线程中逃逸的异常。一旦异常逃出任务的run()方法，他就会向外传播到控制台，除非你采取特殊的步骤捕获这种错误的异常。  (选自Java编程思想)
    当通过ExecutorService 这个接口，来提及任务当时候，通常离不开以下两种方法
    ``` java
      ExecutorService executorService = Executors.newFixedThreadPool(5);
        Future<?> submit = executorService.submit(() -> {
            // do something
        })
        executorService.execute(() -> {
            // do something
        });
    ```
    <!-- 这两个方法都可以用来执行任务，但是区别是execute(）方法的入参是Runnable的函数接口。通过这个接口提交的任务就仅仅做就完了，并没有返回值。
    而 submit()则有不同的重载，入参可以是Callable ，也可以是Runable ,看方法的定义可见这个方法是有返回值的。
   submit() 会将任务执行的结果封装到Future中，等到线程执行完毕之后 -->
    当使用execute 
    ``` java
    public class ExecutorExceptionTest {
        protected static final Logger logger = LogManager.getLogger(ExecutorExceptionTest.class);

        public static void main(String[] args) {
            try {
                logger.info("正常日志输出");
                ExecutorService executorService = Executors.newFixedThreadPool(5);

                executorService.execute(() -> {
                    logger.info("线程池中的线程执行");
                    int i = 1 / 0;
                });
                executorService.shutdown();
                try {
                    executorService.awaitTermination(Integer.MAX_VALUE, TimeUnit.SECONDS);
                } catch (InterruptedException e) {
                    logger.error("InterruptedException:", e);
                }
            } catch (Exception e) {
                logger.error("Exception 已经捕获到:", e);
            }
        }
    }
运行：
    22:44:38.588 [main] INFO  ExecutorExceptionTest - 正常日志输出
    22:44:38.628 [pool-2-thread-1] INFO  ExecutorExceptionTest - 线程池中的线程执行
    Exception in thread "pool-2-thread-1" java.lang.ArithmeticException: / by zero
        at ExecutorExceptionTest.lambda$main$0(ExecutorExceptionTest.java:26)
        at java.util.concurrent.ThreadPoolExecutor.runWorker(ThreadPoolExecutor.java:1149)
        at java.util.concurrent.ThreadPoolExecutor$Worker.run(ThreadPoolExecutor.java:624)
        at java.lang.Thread.run(Thread.java:748)

    ```
    以上信息只有前两行保存到了日志文件中，

